ERROR 2024-03-16 13:22:23,432 Internal Server Error: /auth/users/
Traceback (most recent call last):
  File "C:\Users\rodbe\PycharmProjects\Django + DRF\Some_Store\venv\Lib\site-packages\django\core\handlers\exception.py", line 55, in inner
    response = get_response(request)
               ^^^^^^^^^^^^^^^^^^^^^
  File "C:\Users\rodbe\PycharmProjects\Django + DRF\Some_Store\venv\Lib\site-packages\django\core\handlers\base.py", line 197, in _get_response
    response = wrapped_callback(request, *callback_args, **callback_kwargs)
               ^^^^^^^^^^^^^^^^^^^^^^^^^^^^^^^^^^^^^^^^^^^^^^^^^^^^^^^^^^^^
  File "C:\Users\rodbe\PycharmProjects\Django + DRF\Some_Store\venv\Lib\site-packages\django\views\decorators\csrf.py", line 65, in _view_wrapper
    return view_func(request, *args, **kwargs)
           ^^^^^^^^^^^^^^^^^^^^^^^^^^^^^^^^^^^
  File "C:\Users\rodbe\PycharmProjects\Django + DRF\Some_Store\venv\Lib\site-packages\rest_framework\viewsets.py", line 125, in view
    return self.dispatch(request, *args, **kwargs)
           ^^^^^^^^^^^^^^^^^^^^^^^^^^^^^^^^^^^^^^^
  File "C:\Users\rodbe\PycharmProjects\Django + DRF\Some_Store\venv\Lib\site-packages\rest_framework\views.py", line 509, in dispatch
    response = self.handle_exception(exc)
               ^^^^^^^^^^^^^^^^^^^^^^^^^^
  File "C:\Users\rodbe\PycharmProjects\Django + DRF\Some_Store\venv\Lib\site-packages\rest_framework\views.py", line 469, in handle_exception
    self.raise_uncaught_exception(exc)
  File "C:\Users\rodbe\PycharmProjects\Django + DRF\Some_Store\venv\Lib\site-packages\rest_framework\views.py", line 480, in raise_uncaught_exception
    raise exc
  File "C:\Users\rodbe\PycharmProjects\Django + DRF\Some_Store\venv\Lib\site-packages\rest_framework\views.py", line 506, in dispatch
    response = handler(request, *args, **kwargs)
               ^^^^^^^^^^^^^^^^^^^^^^^^^^^^^^^^^
  File "C:\Users\rodbe\PycharmProjects\Django + DRF\Some_Store\venv\Lib\site-packages\rest_framework\mixins.py", line 19, in create
    self.perform_create(serializer)
  File "C:\Users\rodbe\PycharmProjects\Django + DRF\Some_Store\venv\Lib\site-packages\djoser\views.py", line 140, in perform_create
    settings.EMAIL.activation(self.request, context).send(to)
  File "C:\Users\rodbe\PycharmProjects\Django + DRF\Some_Store\venv\Lib\site-packages\templated_mail\mail.py", line 78, in send
    super(BaseEmailMessage, self).send(*args, **kwargs)
  File "C:\Users\rodbe\PycharmProjects\Django + DRF\Some_Store\venv\Lib\site-packages\django\core\mail\message.py", line 300, in send
    return self.get_connection(fail_silently).send_messages([self])
           ^^^^^^^^^^^^^^^^^^^^^^^^^^^^^^^^^^^^^^^^^^^^^^^^^^^^^^^^
  File "C:\Users\rodbe\PycharmProjects\Django + DRF\Some_Store\venv\Lib\site-packages\django\core\mail\backends\smtp.py", line 127, in send_messages
    new_conn_created = self.open()
                       ^^^^^^^^^^^
  File "C:\Users\rodbe\PycharmProjects\Django + DRF\Some_Store\venv\Lib\site-packages\django\core\mail\backends\smtp.py", line 85, in open
    self.connection = self.connection_class(
                      ^^^^^^^^^^^^^^^^^^^^^^
  File "C:\Users\rodbe\AppData\Local\Programs\Python\Python312\Lib\smtplib.py", line 255, in __init__
    (code, msg) = self.connect(host, port)
                  ^^^^^^^^^^^^^^^^^^^^^^^^
  File "C:\Users\rodbe\AppData\Local\Programs\Python\Python312\Lib\smtplib.py", line 343, in connect
    (code, msg) = self.getreply()
                  ^^^^^^^^^^^^^^^
  File "C:\Users\rodbe\AppData\Local\Programs\Python\Python312\Lib\smtplib.py", line 405, in getreply
    raise SMTPServerDisconnected("Connection unexpectedly closed")
smtplib.SMTPServerDisconnected: Connection unexpectedly closed
